Workbook

Sheet Information

Sheet Depreciation Calculator
C2: Coachx.live
C3: Depreciation Calculator
B5: Straight Line Method
B6: Asset Cost | D6: 450000
B7: Additonal Asset Cost | D7: 50000
B8: Asset Price | D8: =SUM(D6:D7) -> 500000
B9: Scrap Value | D9: 50000
B10: Estimated Life Span (Years) | D10: 10
B11: Depreciation / Year as per Straight Line Method | D11: =IF(D8="", "", SLN($D$8,$D$9,$D$10)) -> 45000
B12: Depreciation Percentage | D12: =IFERROR(D11/D8,"") -> 0.09
B13: Total Depreciation For Its Life Span | D13: =IF(D8="", "", D11*D10) -> 450000
B14: Depreciated Book Value After Its Life Span | D14: =IF(D8="", "", D8-D13) -> 50000
B15: Balance Amount | D15: =IF(D8="", "", D9-D14) -> 0
B17: Diminishing Balance Method
B18: Asset Cost | D18: 450000
B19: Additonal Asset Cost | D19: 50000
B20: Asset Price | D20: =SUM(D18:D19) -> 500000
B21: Scrap Value | D21: 50000
B22: Estimated Life Span (Years) | D22: 10
B23: Rate of Depreciation as per Diminishing Balance Method | D23: =IF(D20="","",1-(D21/D20)^(1/D22)) -> 0.20567177
B24: Depreciation Schedule
B25: Year | C25: Year on Year Depreciation Amount | D25: Book Value
B26: 1 | C26: =IFERROR(IF(D26>$D$21, (D26*$D$23), ""),"") -> 102835.88 | D26: =D8 -> 500000
B27: =B26+1 -> 2 | C27: =IFERROR(IF(D27>$D$21, (D27*$D$23), ""),"") -> 81685.445 | D27: =IFERROR(D26-C26, "") -> 397164.12
B28: =B27+1 -> 3 | C28: =IFERROR(IF(D28>$D$21, (D28*$D$23), ""),"") -> 64885.055 | D28: =IFERROR(D27-C27, "") -> 315478.67
B29: =B28+1 -> 4 | C29: =IFERROR(IF(D29>$D$21, (D29*$D$23), ""),"") -> 51540.032 | D29: =IFERROR(D28-C28, "") -> 250593.62
B30: =B29+1 -> 5 | C30: =IFERROR(IF(D30>$D$21, (D30*$D$23), ""),"") -> 40939.702 | D30: =IFERROR(D29-C29, "") -> 199053.59
B31: =B30+1 -> 6 | C31: =IFERROR(IF(D31>$D$21, (D31*$D$23), ""),"") -> 32519.561 | D31: =IFERROR(D30-C30, "") -> 158113.88
B32: =B31+1 -> 7 | C32: =IFERROR(IF(D32>$D$21, (D32*$D$23), ""),"") -> 25831.206 | D32: =IFERROR(D31-C31, "") -> 125594.32
B33: =B32+1 -> 8 | C33: =IFERROR(IF(D33>$D$21, (D33*$D$23), ""),"") -> 20518.456 | D33: =IFERROR(D32-C32, "") -> 99763.116
B34: =B33+1 -> 9 | C34: =IFERROR(IF(D34>$D$21, (D34*$D$23), ""),"") -> 16298.389 | D34: =IFERROR(D33-C33, "") -> 79244.66
B35: =B34+1 -> 10 | C35: =IFERROR(IF(D35>$D$21, (D35*$D$23), ""),"") -> 12946.271 | D35: =IFERROR(D34-C34, "") -> 62946.271
B36: =B35+1 -> 11 | C36: =IFERROR(IF(D36>$D$21, (D36*$D$23), ""),"") | D36: =IFERROR(D35-C35, "") -> 50000
C37: =IFERROR(IF(D37>$D$21, (D37*$D$23), ""),"") | D37: =IFERROR(D36-C36, "")
C38: =IFERROR(IF(D38>$D$21, (D38*$D$23), ""),"") | D38: =IFERROR(D37-C37, "")
C39: =IFERROR(IF(D39>$D$21, (D39*$D$23), ""),"") | D39: =IFERROR(D38-C38, "")
C40: =IFERROR(IF(D40>$D$21, (D40*$D$23), ""),"") | D40: =IFERROR(D39-C39, "")
C41: =IFERROR(IF(D41>$D$21, (D41*$D$23), ""),"") | D41: =IFERROR(D40-C40, "")
C42: =IFERROR(IF(D42>$D$21, (D42*$D$23), ""),"") | D42: =IFERROR(D41-C41, "")
C43: =IFERROR(IF(D43>$D$21, (D43*$D$23), ""),"") | D43: =IFERROR(D42-C42, "")
...

Sheet Sheet1
A1: 1) Calculate the annual depreciation amount using the straight-
A2: line method for the given asset.
D3: Answer = | E3: ='Depreciation Calculator'!D8-'Depreciation Calculator'!D9/'Depreciation Calculator'!D10 -> 495000
A5: 2) Calculate the total depreciation for the asset's entire life span
A6: using the straight-line method.
C7: Answer = | D7: ='Depreciation Calculator'!D11*'Depreciation Calculator'!D10 -> 450000
A10: 3) What is the depreciated book value of the asset after its life
A11: span using the straight-line method?
E12: Answer = | F12: ='Depreciation Calculator'!D9 -> 50000
A14: 4) Calculate the rate of depreciation per year as per the
A15: diminishing balance method.
E16: Answer = | F16: ='Depreciation Calculator'!D23 -> 0.20567177
A18: 5) What is the depreciation amount for the asset in the second
A19: year according to the diminishing balance method?
G20: Answer= | H20: ='Depreciation Calculator'!C27 -> 81685.445
A23: 6) What is the book value of the asset in the fourth year using
A24: the diminishing balance method?
E25: Answer = | F25: ='Depreciation Calculator'!C29 -> 51540.032
A28: 7) Calculate the total depreciation for the asset's entire life span
A29: using the diminishing balance method.
F30: Answer = | G30: ='Depreciation Calculator'!D26-'Depreciation Calculator'!D36 -> 450000
A33: 8) What is the book value of the asset after its life span using
A34: the diminishing balance method?
E35: Answer = | F35: ='Depreciation Calculator'!D35 -> 62946.271
A37: Compare the total depreciation amounts obtained from the
A38: straight-line method and the diminishing balance method. Which
A39: method results in higher total depreciation?
F40: straight line total depreciation= | H40: ='Depreciation Calculator'!D11*'Depreciation Calculator'!D10 -> 450000
F41: Diminishing Balance Total Deprecation= | I41: ='Depreciation Calculator'!D20-'Depreciation Calculator'!D35 -> 437053.73
F44: The straight line method gives Higher Total Depreciation
